Workbook

Sheet Cover
G1: DATA • INSIGHTS • GROWTH
B17: X | D17: PROJECT
D20: REPORT
A24: ● ● ●
A26: PR. 2 Analyzer – Data Analysis using Microsoft Excel
B29: Submitted by | E29: Thakkar Disha
B30: GR ID | E30: 12782
B31: Date | E31: 46304
A33: Analyze • Create • Achieve

Sheet Contents
A1: Contents (click a name to open the sheet)
A2: 1 | B2: Project Instructions | C2: Topics, main tasks and deliverable (with sheet map)
A3: 2 | B3: Dataset | C3: 200 orders with sales, discount, profit and NOW() timestamp
A4: 3 | B4: Customer Analysis | C4: Total purchase per customer, top 10 highlighted
A5: 4 | B5: High Value Customers | C5: LARGE + INDEX + MATCH list and customer lookup
A6: 5 | B6: What-If Analysis | C6: Effect of discount on total profit, Goal Seek set-up
A7: 6 | B7: Regression | C7: Linear regression output (Profit vs Sales), ToolPak style
A8: 7 | B8: Descriptive Stats | C8: Descriptive statistics, advanced analytics, histogram data
A9: 8 | B9: Monthly Trend | C9: Monthly sales with up/down growth arrows
A10: 9 | B10: Pivot Summary | C10: Total sales by region and product + pivot how-to
A11: 10 | B11: Charts | C11: Bar, line, pie, histogram, what-if line and regression scatter
A12: 11 | B12: Dashboard | C12: KPIs, charts and key insights

Sheet Project Instructions
A1: PR. 2 Analyzer – Project Instructions
A3: Topics
A4: Conditional Formatting
A5: WHAT IF Analysis
A6: Linear Regression (Using Data Analysis ToolPak)
A7: Data Analysis Feature (Descriptive Stats, Regression, Histogram)
A8: Data Storytelling
A9: Add Symbols or Arrows in Custom Formatting
A10: Create Timestamp
A11: Find High-Value Customers using GroupBy(), INDEX() and MATCH() combination
A12: Advanced Descriptive Analytics
A13: Pivot Table with Dashboard
... A36: Blue text / yellow fill = cells you can edit. Black = formulas.

Sheet Dataset
A1: Customer_ID | B1: Customer_Name | C1: Region | D1: Product_Category | E1: Sales | F1: Quantity | G1: Discount | H1: Order_Date | I1: Profit | J1: Timestamp (NOW) | K1: Month Start | L1: Gross Sales (before discount) | M1: Cost (Sales − Profit) | N1: Profit Margin
A2: CUST019 | B2: James Davis | C2: West | D2: Books | E2: 1036.09 | F2: 4 | G2: 0.2 | H2: 45392 | I2: 331.55 | J2: =NOW() -> 46304.471 | K2: =DATE(YEAR(H2),MONTH(H2),1) -> 45383 | L2: =E2/(1-G2) -> 1295.1125 | M2: =E2-I2 -> 704.54 | N2: =I2/E2 -> 0.32000116
A3: CUST012 | B3: Robert Anderson | C3: West | D3: Clothing | E3: 1101.28 | F3: 3 | G3: 0.2 | H3: 45393 | I3: 440.51 | J3: =NOW() -> 46304.471 | K3: =DATE(YEAR(H3),MONTH(H3),1) -> 45383 | L3: =E3/(1-G3) -> 1376.6 | M3: =E3-I3 -> 660.77 | N3: =I3/E3 -> 0.39999818
A4: CUST017 | B4: James Taylor | C4: East | D4: Books | E4: 713.34 | F4: 17 | G4: 0 | H4: 45396 | I4: 285.34 | J4: =NOW() -> 46304.471 | K4: =DATE(YEAR(H4),MONTH(H4),1) -> 45383 | L4: =E4/(1-G4) -> 713.34 | M4: =E4-I4 -> 428 | N4: =I4/E4 -> 0.40000561
A5: CUST005 | B5: Robert Anderson | C5: South | D5: Electronics | E5: 760.93 | F5: 4 | G5: 0.15 | H5: 45396 | I5: 161.7 | J5: =NOW() -> 46304.471 | K5: =DATE(YEAR(H5),MONTH(H5),1) -> 45383 | L5: =E5/(1-G5) -> 895.21176 | M5: =E5-I5 -> 599.23 | N5: =I5/E5 -> 0.21250312
A6: CUST030 | B6: James Wilson | C6: North | D6: Books | E6: 847 | F6: 12 | G6: 0.2 | H6: 45397 | I6: 271.04 | J6: =NOW() -> 46304.471 | K6: =DATE(YEAR(H6),MONTH(H6),1) -> 45383 | L6: =E6/(1-G6) -> 1058.75 | M6: =E6-I6 -> 575.96 | N6: =I6/E6 -> 0.32
A7: CUST007 | B7: Michael Anderson | C7: North | D7: Furniture | E7: 965.64 | F7: 8 | G7: 0.1 | H7: 45398 | I7: 304.18 | J7: =NOW() -> 46304.471 | K7: =DATE(YEAR(H7),MONTH(H7),1) -> 45383 | L7: =E7/(1-G7) -> 1072.9333 | M7: =E7-I7 -> 661.46 | N7: =I7/E7 -> 0.31500352
A8: CUST001 | B8: Linda Wilson | C8: West | D8: Electronics | E8: 1317.53 | F8: 12 | G8: 0.05 | H8: 45398 | I8: 312.91 | J8: =NOW() -> 46304.471 | K8: =DATE(YEAR(H8),MONTH(H8),1) -> 45383 | L8: =E8/(1-G8) -> 1386.8737 | M8: =E8-I8 -> 1004.62 | N8: =I8/E8 -> 0.23749744
A9: CUST026 | B9: Mary Davis | C9: East | D9: Furniture | E9: 1074.47 | F9: 6 | G9: 0.2 | H9: 45401 | I9: 300.85 | J9: =NOW() -> 46304.471 | K9: =DATE(YEAR(H9),MONTH(H9),1) -> 45383 | L9: =E9/(1-G9) -> 1343.0875 | M9: =E9-I9 -> 773.62 | N9: =I9/E9 -> 0.27999851
A10: CUST009 | B10: Linda Jackson | C10: Central | D10: Books | E10: 501.54 | F10: 11 | G10: 0.05 | H10: 45401 | I10: 190.59 | J10: =NOW() -> 46304.471 | K10: =DATE(YEAR(H10),MONTH(H10),1) -> 45383 | L10: =E10/(1-G10) -> 527.93684 | M10: =E10-I10 -> 310.95 | N10: =I10/E10 -> 0.38000957
A11: CUST010 | B11: David Thomas | C11: Central | D11: Clothing | E11: 737.31 | F11: 2 | G11: 0.05 | H11: 45401 | I11: 350.22 | J11: =NOW() -> 46304.471 | K11: =DATE(YEAR(H11),MONTH(H11),1) -> 45383 | L11: =E11/(1-G11) -> 776.11579 | M11: =E11-I11 -> 387.09 | N11: =I11/E11 -> 0.47499695
A12: CUST014 | B12: Emma Davis | C12: West | D12: Office Supplies | E12: 1572.82 | F12: 6 | G12: 0.05 | H12: 45402 | I12: 672.38 | J12: =NOW() -> 46304.471 | K12: =DATE(YEAR(H12),MONTH(H12),1) -> 45383 | L12: =E12/(1-G12) -> 1655.6 | M12: =E12-I12 -> 900.44 | N12: =I12/E12 -> 0.42749965
A13: CUST014 | B13: David Thomas | C13: Central | D13: Books | E13: 1343.13 | F13: 14 | G13: 0.15 | H13: 45404 | I13: 456.66 | J13: =NOW() -> 46304.471 | K13: =DATE(YEAR(H13),MONTH(H13),1) -> 45383 | L13: =E13/(1-G13) -> 1580.1529 | M13: =E13-I13 -> 886.47 | N13: =I13/E13 -> 0.33999687
... A201: CUST016 | B201: David Thomas | C201: South | D201: Clothing | E201: 928.32 | F201: 2 | G201: 0.05 | H201: 45754 | I201: 440.95 | J201: =NOW() -> 46304.471 | K201: =DATE(YEAR(H201),MONTH(H201),1) -> 45748 | L201: =E201/(1-G201) -> 977.17895 | M201: =E201-I201 -> 487.37 | N201: =I201/E201 -> 0.47499785

Sheet Customer Analysis
A1: Customer Analysis – total purchase per customer (top 10 highlighted)
A2: Total Sales = SUMIFS by Customer_ID. Top 10 rows are highlighted with conditional formatting (Rank ≤ 10).
A3: Customer_ID | B3: Orders | C3: Total Sales | D3: Total Profit | E3: Avg Discount | F3: Rank | G3: Top 10? | H3: Segment
A4: CUST015 | B4: =COUNTIF(Dataset!$A$2:$A$201,A4) -> 11 | C4: =SUMIFS(Dataset!$E$2:$E$201,Dataset!$A$2:$A$201,A4) -> 11611.06 | D4: =SUMIFS(Dataset!$I$2:$I$201,Dataset!$A$2:$A$201,A4) -> 4201.59 | E4: =AVERAGEIFS(Dataset!$G$2:$G$201,Dataset!$A$2:$A$201,A4) -> 0.10454545 | F4: =RANK(C4,$C$4:$C$33) -> 1 | G4: =IF(F4<=10,"★ Top 10","") -> ★ Top 10 | H4: =IF(C4>='High Value Customers'!$B$3,"High-Value","Standard") -> High-Value
A5: CUST028 | B5: =COUNTIF(Dataset!$A$2:$A$201,A5) -> 12 | C5: =SUMIFS(Dataset!$E$2:$E$201,Dataset!$A$2:$A$201,A5) -> 10293.87 | D5: =SUMIFS(Dataset!$I$2:$I$201,Dataset!$A$2:$A$201,A5) -> 3541.02 | E5: =AVERAGEIFS(Dataset!$G$2:$G$201,Dataset!$A$2:$A$201,A5) -> 0.12083333 | F5: =RANK(C5,$C$4:$C$33) -> 2 | G5: =IF(F5<=10,"★ Top 10","") -> ★ Top 10 | H5: =IF(C5>='High Value Customers'!$B$3,"High-Value","Standard") -> High-Value
A6: CUST007 | B6: =COUNTIF(Dataset!$A$2:$A$201,A6) -> 10 | C6: =SUMIFS(Dataset!$E$2:$E$201,Dataset!$A$2:$A$201,A6) -> 9941.88 | D6: =SUMIFS(Dataset!$I$2:$I$201,Dataset!$A$2:$A$201,A6) -> 3936.26 | E6: =AVERAGEIFS(Dataset!$G$2:$G$201,Dataset!$A$2:$A$201,A6) -> 0.04 | F6: =RANK(C6,$C$4:$C$33) -> 3 | G6: =IF(F6<=10,"★ Top 10","") -> ★ Top 10 | H6: =IF(C6>='High Value Customers'!$B$3,"High-Value","Standard") -> High-Value
A7: CUST008 | B7: =COUNTIF(Dataset!$A$2:$A$201,A7) -> 10 | C7: =SUMIFS(Dataset!$E$2:$E$201,Dataset!$A$2:$A$201,A7) -> 9760.8 | D7: =SUMIFS(Dataset!$I$2:$I$201,Dataset!$A$2:$A$201,A7) -> 3442.48 | E7: =AVERAGEIFS(Dataset!$G$2:$G$201,Dataset!$A$2:$A$201,A7) -> 0.105 | F7: =RANK(C7,$C$4:$C$33) -> 4 | G7: =IF(F7<=10,"★ Top 10","") -> ★ Top 10 | H7: =IF(C7>='High Value Customers'!$B$3,"High-Value","Standard") -> High-Value
A8: CUST026 | B8: =COUNTIF(Dataset!$A$2:$A$201,A8) -> 9 | C8: =SUMIFS(Dataset!$E$2:$E$201,Dataset!$A$2:$A$201,A8) -> 9371.81 | D8: =SUMIFS(Dataset!$I$2:$I$201,Dataset!$A$2:$A$201,A8) -> 2922.02 | E8: =AVERAGEIFS(Dataset!$G$2:$G$201,Dataset!$A$2:$A$201,A8) -> 0.077777778 | F8: =RANK(C8,$C$4:$C$33) -> 5 | G8: =IF(F8<=10,"★ Top 10","") -> ★ Top 10 | H8: =IF(C8>='High Value Customers'!$B$3,"High-Value","Standard") -> High-Value
A9: CUST021 | B9: =COUNTIF(Dataset!$A$2:$A$201,A9) -> 8 | C9: =SUMIFS(Dataset!$E$2:$E$201,Dataset!$A$2:$A$201,A9) -> 8740.18 | D9: =SUMIFS(Dataset!$I$2:$I$201,Dataset!$A$2:$A$201,A9) -> 2848.62 | E9: =AVERAGEIFS(Dataset!$G$2:$G$201,Dataset!$A$2:$A$201,A9) -> 0.1125 | F9: =RANK(C9,$C$4:$C$33) -> 6 | G9: =IF(F9<=10,"★ Top 10","") -> ★ Top 10 | H9: =IF(C9>='High Value Customers'!$B$3,"High-Value","Standard") -> High-Value
A10: CUST003 | B10: =COUNTIF(Dataset!$A$2:$A$201,A10) -> 9 | C10: =SUMIFS(Dataset!$E$2:$E$201,Dataset!$A$2:$A$201,A10) -> 8490.18 | D10: =SUMIFS(Dataset!$I$2:$I$201,Dataset!$A$2:$A$201,A10) -> 2652.75 | E10: =AVERAGEIFS(Dataset!$G$2:$G$201,Dataset!$A$2:$A$201,A10) -> 0.12222222 | F10: =RANK(C10,$C$4:$C$33) -> 7 | G10: =IF(F10<=10,"★ Top 10","") -> ★ Top 10 | H10: =IF(C10>='High Value Customers'!$B$3,"High-Value","Standard") -> High-Value
A11: CUST012 | B11: =COUNTIF(Dataset!$A$2:$A$201,A11) -> 9 | C11: =SUMIFS(Dataset!$E$2:$E$201,Dataset!$A$2:$A$201,A11) -> 8339 | D11: =SUMIFS(Dataset!$I$2:$I$201,Dataset!$A$2:$A$201,A11) -> 2988.71 | E11: =AVERAGEIFS(Dataset!$G$2:$G$201,Dataset!$A$2:$A$201,A11) -> 0.094444444 | F11: =RANK(C11,$C$4:$C$33) -> 8 | G11: =IF(F11<=10,"★ Top 10","") -> ★ Top 10 | H11: =IF(C11>='High Value Customers'!$B$3,"High-Value","Standard") -> High-Value
A12: CUST030 | B12: =COUNTIF(Dataset!$A$2:$A$201,A12) -> 9 | C12: =SUMIFS(Dataset!$E$2:$E$201,Dataset!$A$2:$A$201,A12) -> 7928.71 | D12: =SUMIFS(Dataset!$I$2:$I$201,Dataset!$A$2:$A$201,A12) -> 2965.48 | E12: =AVERAGEIFS(Dataset!$G$2:$G$201,Dataset!$A$2:$A$201,A12) -> 0.088888889 | F12: =RANK(C12,$C$4:$C$33) -> 9 | G12: =IF(F12<=10,"★ Top 10","") -> ★ Top 10 | H12: =IF(C12>='High Value Customers'!$B$3,"High-Value","Standard") -> Standard
A13: CUST004 | B13: =COUNTIF(Dataset!$A$2:$A$201,A13) -> 7 | C13: =SUMIFS(Dataset!$E$2:$E$201,Dataset!$A$2:$A$201,A13) -> 7813.59 | D13: =SUMIFS(Dataset!$I$2:$I$201,Dataset!$A$2:$A$201,A13) -> 3211.82 | E13: =AVERAGEIFS(Dataset!$G$2:$G$201,Dataset!$A$2:$A$201,A13) -> 0.085714286 | F13: =RANK(C13,$C$4:$C$33) -> 10 | G13: =IF(F13<=10,"★ Top 10","") -> ★ Top 10 | H13: =IF(C13>='High Value Customers'!$B$3,"High-Value","Standard") -> Standard
A14: CUST024 | B14: =COUNTIF(Dataset!$A$2:$A$201,A14) -> 7 | C14: =SUMIFS(Dataset!$E$2:$E$201,Dataset!$A$2:$A$201,A14) -> 7583.13 | D14: =SUMIFS(Dataset!$I$2:$I$201,Dataset!$A$2:$A$201,A14) -> 2492.1 | E14: =AVERAGEIFS(Dataset!$G$2:$G$201,Dataset!$A$2:$A$201,A14) -> 0.15714286 | F14: =RANK(C14,$C$4:$C$33) -> 11 | G14: =IF(F14<=10,"★ Top 10","") | H14: =IF(C14>='High Value Customers'!$B$3,"High-Value","Standard") -> Standard
A15: CUST014 | B15: =COUNTIF(Dataset!$A$2:$A$201,A15) -> 6 | C15: =SUMIFS(Dataset!$E$2:$E$201,Dataset!$A$2:$A$201,A15) -> 6729.89 | D15: =SUMIFS(Dataset!$I$2:$I$201,Dataset!$A$2:$A$201,A15) -> 2507.18 | E15: =AVERAGEIFS(Dataset!$G$2:$G$201,Dataset!$A$2:$A$201,A15) -> 0.11666667 | F15: =RANK(C15,$C$4:$C$33) -> 12 | G15: =IF(F15<=10,"★ Top 10","") | H15: =IF(C15>='High Value Customers'!$B$3,"High-Value","Standard") -> Standard
... A33: CUST006 | B33: =COUNTIF(Dataset!$A$2:$A$201,A33) -> 2 | C33: =SUMIFS(Dataset!$E$2:$E$201,Dataset!$A$2:$A$201,A33) -> 2699.75 | D33: =SUMIFS(Dataset!$I$2:$I$201,Dataset!$A$2:$A$201,A33) -> 837.06 | E33: =AVERAGEIFS(Dataset!$G$2:$G$201,Dataset!$A$2:$A$201,A33) -> 0.175 | F33: =RANK(C33,$C$4:$C$33) -> 30 | G33: =IF(F33<=10,"★ Top 10","") | H33: =IF(C33>='High Value Customers'!$B$3,"High-Value","Standard") -> Standard
A34: Total | B34: =SUM(B4:B33) -> 200 | C34: =SUM(C4:C33) -> 195217.76 | D34: =SUM(D4:D33) -> 68287.01

Sheet High Value Customers
A1: High-Value Customers – LARGE + INDEX + MATCH
A3: High-value threshold (75th percentile of total sales) | B3: =PERCENTILE('Customer Analysis'!C4:C33,0.75) -> 8236.4275
A4: Number of high-value customers | B4: =COUNTIF('Customer Analysis'!C4:C33,">="&B3) -> 8
A6: Rank | B6: Total Sales (LARGE) | C6: Customer_ID (INDEX/MATCH) | D6: Orders | E6: Total Profit | F6: Status
A7: 1 | B7: =LARGE('Customer Analysis'!$C$4:$C$33,A7) -> 11611.06 | C7: =INDEX('Customer Analysis'!$A$4:$A$33,MATCH(B7,'Customer Analysis'!$C$4:$C$33,0)) -> CUST015 | D7: =INDEX('Customer Analysis'!$B$4:$B$33,MATCH(C7,'Customer Analysis'!$A$4:$A$33,0)) -> 11 | E7: =INDEX('Customer Analysis'!$D$4:$D$33,MATCH(C7,'Customer Analysis'!$A$4:$A$33,0)) -> 4201.59 | F7: =IF(B7>=$B$3,"High-Value","Standard") -> High-Value
A8: 2 | B8: =LARGE('Customer Analysis'!$C$4:$C$33,A8) -> 10293.87 | C8: =INDEX('Customer Analysis'!$A$4:$A$33,MATCH(B8,'Customer Analysis'!$C$4:$C$33,0)) -> CUST028 | D8: =INDEX('Customer Analysis'!$B$4:$B$33,MATCH(C8,'Customer Analysis'!$A$4:$A$33,0)) -> 12 | E8: =INDEX('Customer Analysis'!$D$4:$D$33,MATCH(C8,'Customer Analysis'!$A$4:$A$33,0)) -> 3541.02 | F8: =IF(B8>=$B$3,"High-Value","Standard") -> High-Value
A9: 3 | B9: =LARGE('Customer Analysis'!$C$4:$C$33,A9) -> 9941.88 | C9: =INDEX('Customer Analysis'!$A$4:$A$33,MATCH(B9,'Customer Analysis'!$C$4:$C$33,0)) -> CUST007 | D9: =INDEX('Customer Analysis'!$B$4:$B$33,MATCH(C9,'Customer Analysis'!$A$4:$A$33,0)) -> 10 | E9: =INDEX('Customer Analysis'!$D$4:$D$33,MATCH(C9,'Customer Analysis'!$A$4:$A$33,0)) -> 3936.26 | F9: =IF(B9>=$B$3,"High-Value","Standard") -> High-Value
A10: 4 | B10: =LARGE('Customer Analysis'!$C$4:$C$33,A10) -> 9760.8 | C10: =INDEX('Customer Analysis'!$A$4:$A$33,MATCH(B10,'Customer Analysis'!$C$4:$C$33,0)) -> CUST008 | D10: =INDEX('Customer Analysis'!$B$4:$B$33,MATCH(C10,'Customer Analysis'!$A$4:$A$33,0)) -> 10 | E10: =INDEX('Customer Analysis'!$D$4:$D$33,MATCH(C10,'Customer Analysis'!$A$4:$A$33,0)) -> 3442.48 | F10: =IF(B10>=$B$3,"High-Value","Standard") -> High-Value
A11: 5 | B11: =LARGE('Customer Analysis'!$C$4:$C$33,A11) -> 9371.81 | C11: =INDEX('Customer Analysis'!$A$4:$A$33,MATCH(B11,'Customer Analysis'!$C$4:$C$33,0)) -> CUST026 | D11: =INDEX('Customer Analysis'!$B$4:$B$33,MATCH(C11,'Customer Analysis'!$A$4:$A$33,0)) -> 9 | E11: =INDEX('Customer Analysis'!$D$4:$D$33,MATCH(C11,'Customer Analysis'!$A$4:$A$33,0)) -> 2922.02 | F11: =IF(B11>=$B$3,"High-Value","Standard") -> High-Value
A12: 6 | B12: =LARGE('Customer Analysis'!$C$4:$C$33,A12) -> 8740.18 | C12: =INDEX('Customer Analysis'!$A$4:$A$33,MATCH(B12,'Customer Analysis'!$C$4:$C$33,0)) -> CUST021 | D12: =INDEX('Customer Analysis'!$B$4:$B$33,MATCH(C12,'Customer Analysis'!$A$4:$A$33,0)) -> 8 | E12: =INDEX('Customer Analysis'!$D$4:$D$33,MATCH(C12,'Customer Analysis'!$A$4:$A$33,0)) -> 2848.62 | F12: =IF(B12>=$B$3,"High-Value","Standard") -> High-Value
A13: 7 | B13: =LARGE('Customer Analysis'!$C$4:$C$33,A13) -> 8490.18 | C13: =INDEX('Customer Analysis'!$A$4:$A$33,MATCH(B13,'Customer Analysis'!$C$4:$C$33,0)) -> CUST003 | D13: =INDEX('Customer Analysis'!$B$4:$B$33,MATCH(C13,'Customer Analysis'!$A$4:$A$33,0)) -> 9 | E13: =INDEX('Customer Analysis'!$D$4:$D$33,MATCH(C13,'Customer Analysis'!$A$4:$A$33,0)) -> 2652.75 | F13: =IF(B13>=$B$3,"High-Value","Standard") -> High-Value
A14: 8 | B14: =LARGE('Customer Analysis'!$C$4:$C$33,A14) -> 8339 | C14: =INDEX('Customer Analysis'!$A$4:$A$33,MATCH(B14,'Customer Analysis'!$C$4:$C$33,0)) -> CUST012 | D14: =INDEX('Customer Analysis'!$B$4:$B$33,MATCH(C14,'Customer Analysis'!$A$4:$A$33,0)) -> 9 | E14: =INDEX('Customer Analysis'!$D$4:$D$33,MATCH(C14,'Customer Analysis'!$A$4:$A$33,0)) -> 2988.71 | F14: =IF(B14>=$B$3,"High-Value","Standard") -> High-Value
A15: 9 | B15: =LARGE('Customer Analysis'!$C$4:$C$33,A15) -> 7928.71 | C15: =INDEX('Customer Analysis'!$A$4:$A$33,MATCH(B15,'Customer Analysis'!$C$4:$C$33,0)) -> CUST030 | D15: =INDEX('Customer Analysis'!$B$4:$B$33,MATCH(C15,'Customer Analysis'!$A$4:$A$33,0)) -> 9 | E15: =INDEX('Customer Analysis'!$D$4:$D$33,MATCH(C15,'Customer Analysis'!$A$4:$A$33,0)) -> 2965.48 | F15: =IF(B15>=$B$3,"High-Value","Standard") -> Standard
A16: 10 | B16: =LARGE('Customer Analysis'!$C$4:$C$33,A16) -> 7813.59 | C16: =INDEX('Customer Analysis'!$A$4:$A$33,MATCH(B16,'Customer Analysis'!$C$4:$C$33,0)) -> CUST004 | D16: =INDEX('Customer Analysis'!$B$4:$B$33,MATCH(C16,'Customer Analysis'!$A$4:$A$33,0)) -> 7 | E16: =INDEX('Customer Analysis'!$D$4:$D$33,MATCH(C16,'Customer Analysis'!$A$4:$A$33,0)) -> 3211.82 | F16: =IF(B16>=$B$3,"High-Value","Standard") -> Standard
A19: Customer lookup (pick a Customer_ID)
A20: Customer_ID → | B20: CUST015
A21: Orders | B21: =INDEX('Customer Analysis'!$B$4:$B$33,MATCH($B$20,'Customer Analysis'!$A$4:$A$33,0)) -> 11
A22: Total Sales | B22: =INDEX('Customer Analysis'!$C$4:$C$33,MATCH($B$20,'Customer Analysis'!$A$4:$A$33,0)) -> 11611.06
A23: Total Profit | B23: =INDEX('Customer Analysis'!$D$4:$D$33,MATCH($B$20,'Customer Analysis'!$A$4:$A$33,0)) -> 4201.59
A24: Avg Discount | B24: =INDEX('Customer Analysis'!$E$4:$E$33,MATCH($B$20,'Customer Analysis'!$A$4:$A$33,0)) -> 0.10454545
A25: Rank | B25: =INDEX('Customer Analysis'!$F$4:$F$33,MATCH($B$20,'Customer Analysis'!$A$4:$A$33,0)) -> 1
A26: Segment | B26: =INDEX('Customer Analysis'!$H$4:$H$33,MATCH($B$20,'Customer Analysis'!$A$4:$A$33,0)) -> High-Value

Sheet What-If Analysis
A1: What-If Analysis – impact of changing discount on total profit
A3: Baseline (actual data) | B3: Value
A4: Total sales (actual) | B4: =SUM(Dataset!$E$2:$E$201) -> 195217.76
A5: Total profit (actual) | B5: =SUM(Dataset!$I$2:$I$201) -> 68287.01
A6: Average discount (actual) | B6: =AVERAGE(Dataset!$G$2:$G$201) -> 0.09725
A7: Total gross sales (before discount) | B7: =SUM(Dataset!$L$2:$L$201) -> 218027.19
A8: Total cost (Sales − Profit) | B8: =SUM(Dataset!$M$2:$M$201) -> 126930.75
A10: Scenario – apply one discount to all orders
A11: New discount % (input) | B11: 0.1
A12: Scenario sales | B12: =B7*(1-B11) -> 196224.47
A13: Scenario total profit | B13: =B12-B8 -> 69293.725
A14: Change vs actual profit | B14: =B13-B5 -> 1006.7146
A15: Change % | B15: =B14/B5 -> 0.014742402
A17: Discount % | B17: Total Sales | C17: Total Profit | D17: Profit Margin
A18: 0 | B18: =$B$7*(1-A18) -> 218027.19 | C18: =B18-$B$8 -> 91096.444 | D18: =C18/B18 -> 0.41782148
A19: 0.05 | B19: =$B$7*(1-A19) -> 207125.83 | C19: =B19-$B$8 -> 80195.084 | D19: =C19/B19 -> 0.3871805
A20: 0.1 | B20: =$B$7*(1-A20) -> 196224.47 | C20: =B20-$B$8 -> 69293.725 | D20: =C20/B20 -> 0.35313497
A21: 0.15 | B21: =$B$7*(1-A21) -> 185323.11 | C21: =B21-$B$8 -> 58392.365 | D21: =C21/B21 -> 0.31508409
A22: 0.2 | B22: =$B$7*(1-A22) -> 174421.76 | C22: =B22-$B$8 -> 47491.005 | D22: =C22/B22 -> 0.27227684
A23: 0.25 | B23: =$B$7*(1-A23) -> 163520.4 | C23: =B23-$B$8 -> 36589.645 | D23: =C23/B23 -> 0.22376197
A24: 0.3 | B24: =$B$7*(1-A24) -> 152619.04 | C24: =B24-$B$8 -> 25688.286 | D24: =C24/B24 -> 0.16831639
A27: Goal Seek
A28: Target total profit (= actual +10%) | B28: =B5*1.1 -> 75115.711
A29: Discount needed (closed-form check) | B29: =1-(B28+B8)/B7 -> 0.073296971
A31: Assumptions: gross sales = Sales ÷ (1 − Discount); cost per order = Sales − Profit and stays fixed; quantity sold does not change with discount.
A32: Goal Seek: Data > What-If Analysis > Goal Seek → Set cell B13, To value = B28, By changing cell B11 (result should match B29).
A33: Scenario Manager: Data > What-If Analysis > Scenario Manager → add scenarios (5%, 10%, 20%) changing B11; Summary result cell = B13.

Sheet Regression
A1: Linear Regression: Profit (Y) vs Sales (X) – Analysis ToolPak style output
A3: SUMMARY OUTPUT
A4: Regression Statistics
A5: Multiple R | B5: =SQRT(B6) -> 0.77340306
A6: R Square | B6: =RSQ(Dataset!$I$2:$I$201,Dataset!$E$2:$E$201) -> 0.5981523
A7: Adjusted R Square | B7: =1-(1-B6)*(B9-1)/(B9-2) -> 0.59612277
A8: Standard Error | B8: =STEYX(Dataset!$I$2:$I$201,Dataset!$E$2:$E$201) -> 86.281231
A9: Observations | B9: =COUNT(Dataset!$E$2:$E$201) -> 200
A11: ANOVA | B11: df | C11: SS | D11: MS | E11: F | F11: Significance F
A12: Regression | B12: 1 | C12: =B6*DEVSQ(Dataset!$I$2:$I$201) -> 2194058.2 | D12: =C12/B12 -> 2194058.2 | E12: =D12/D13 -> 294.72398 | F12: =FDIST(E12,B12,B13) -> 4.6269368e-41
A13: Residual | B13: =B9-2 -> 198 | C13: =C14-C12 -> 1474001.2 | D13: =C13/B13 -> 7444.4507
A14: Total | B14: =B9-1 -> 199 | C14: =DEVSQ(Dataset!$I$2:$I$201) -> 3668059.4
B16: Coefficients | C16: Standard Error | D16: t Stat | E16: P-value | F16: Lower 95% | G16: Upper 95%
A17: Intercept | B17: =INTERCEPT(Dataset!$I$2:$I$201,Dataset!$E$2:$E$201) -> -1.0315505 | C17: =B8*SQRT(1/B9+AVERAGE(Dataset!$E$2:$E$201)^2/DEVSQ(Dataset!$E$2:$E$201)) -> 20.860617 | D17: =B17/C17 -> -0.049449663 | E17: =TDIST(ABS(D17),$B$13,2) -> 0.9606108 | F17: =B17-TINV(0.05,$B$13)*C17 -> -42.169052 | G17: =B17+TINV(0.05,$B$13)*C17 -> 40.105951
A18: Sales (X) | B18: =SLOPE(Dataset!$I$2:$I$201,Dataset!$E$2:$E$201) -> 0.35085599 | C18: =B8/SQRT(DEVSQ(Dataset!$E$2:$E$201)) -> 0.020437189 | D18: =B18/C18 -> 17.167527 | E18: =TDIST(ABS(D18),$B$13,2) -> 4.6269368e-41 | F18: =B18-TINV(0.05,$B$13)*C18 -> 0.3105535 | G18: =B18+TINV(0.05,$B$13)*C18 -> 0.39115848
A21: Predict profit for sales of → | B21: 1000
A22: Predicted profit | B22: =B17+B18*B21 -> 349.82444
A24: ="Interpretation: each extra 1 unit of Sales adds about "&TEXT(B18,"0.000")&" units of Profit; Sales explains "&TEXT(B6,"0.0%")&" of the variation in Profit ("&IF(E18<0.05,"statistically significant","not significant")&" at 5%)." -> Interpretation: each extra 1 unit of Sales adds about 0.351 units of Profit; Sales explains 59.8% of the variation in Profit (statistically significant at 5%).
A27: To reproduce with the ToolPak: Data > Data Analysis > Regression, Input Y = Dataset!I2:I201, Input X = Dataset!E2:E201.

Sheet Descriptive Stats
A1: Descriptive Statistics (ToolPak style) & Advanced Descriptive Analytics
A3: Statistic | B3: Sales | C3: Quantity | D3: Discount | E3: Profit
A4: Mean | B4: =AVERAGE(Dataset!$E$2:$E$201) -> 976.0888 | C4: =AVERAGE(Dataset!$F$2:$F$201) -> 9.995 | D4: =AVERAGE(Dataset!$G$2:$G$201) -> 0.09725 | E4: =AVERAGE(Dataset!$I$2:$I$201) -> 341.43505
A5: Standard Error | B5: =STDEV(Dataset!$E$2:$E$201)/SQRT(COUNT(Dataset!$E$2:$E$201)) -> 21.16185 | C5: =STDEV(Dataset!$F$2:$F$201)/SQRT(COUNT(Dataset!$F$2:$F$201)) -> 0.39927683 | D5: =STDEV(Dataset!$G$2:$G$201)/SQRT(COUNT(Dataset!$G$2:$G$201)) -> 0.0051142414 | E5: =STDEV(Dataset!$I$2:$I$201)/SQRT(COUNT(Dataset!$I$2:$I$201)) -> 9.6001196
A6: Median | B6: =MEDIAN(Dataset!$E$2:$E$201) -> 976.72 | C6: =MEDIAN(Dataset!$F$2:$F$201) -> 10 | D6: =MEDIAN(Dataset!$G$2:$G$201) -> 0.1 | E6: =MEDIAN(Dataset!$I$2:$I$201) -> 332.255
A7: Mode | B7: =IFERROR(MODE(Dataset!$E$2:$E$201),"No mode") -> No mode | C7: =IFERROR(MODE(Dataset!$F$2:$F$201),"No mode") -> 8 | D7: =IFERROR(MODE(Dataset!$G$2:$G$201),"No mode") -> 0 | E7: =IFERROR(MODE(Dataset!$I$2:$I$201),"No mode") -> No mode
A8: Standard Deviation | B8: =STDEV(Dataset!$E$2:$E$201) -> 299.27376 | C8: =STDEV(Dataset!$F$2:$F$201) -> 5.646627 | D8: =STDEV(Dataset!$G$2:$G$201) -> 0.072326295 | E8: =STDEV(Dataset!$I$2:$I$201) -> 135.76619
A9: Sample Variance | B9: =VAR(Dataset!$E$2:$E$201) -> 89564.783 | C9: =VAR(Dataset!$F$2:$F$201) -> 31.884397 | D9: =VAR(Dataset!$G$2:$G$201) -> 0.005231093 | E9: =VAR(Dataset!$I$2:$I$201) -> 18432.459
A10: Kurtosis | B10: =KURT(Dataset!$E$2:$E$201) -> -0.088595232 | C10: =KURT(Dataset!$F$2:$F$201) -> -1.2091054 | D10: =KURT(Dataset!$G$2:$G$201) -> -1.3257012 | E10: =KURT(Dataset!$I$2:$I$201) -> 0.26450644
A11: Skewness | B11: =SKEW(Dataset!$E$2:$E$201) -> 0.14685797 | C11: =SKEW(Dataset!$F$2:$F$201) -> 0.060845864 | D11: =SKEW(Dataset!$G$2:$G$201) -> 0.096827386 | E11: =SKEW(Dataset!$I$2:$I$201) -> 0.57339636
A12: Range | B12: =MAX(Dataset!$E$2:$E$201)-MIN(Dataset!$E$2:$E$201) -> 1665.15 | C12: =MAX(Dataset!$F$2:$F$201)-MIN(Dataset!$F$2:$F$201) -> 18 | D12: =MAX(Dataset!$G$2:$G$201)-MIN(Dataset!$G$2:$G$201) -> 0.2 | E12: =MAX(Dataset!$I$2:$I$201)-MIN(Dataset!$I$2:$I$201) -> 704.83
A13: Minimum | B13: =MIN(Dataset!$E$2:$E$201) -> 258.51 | C13: =MIN(Dataset!$F$2:$F$201) -> 1 | D13: =MIN(Dataset!$G$2:$G$201) -> 0 | E13: =MIN(Dataset!$I$2:$I$201) -> 64.63
A14: Maximum | B14: =MAX(Dataset!$E$2:$E$201) -> 1923.66 | C14: =MAX(Dataset!$F$2:$F$201) -> 19 | D14: =MAX(Dataset!$G$2:$G$201) -> 0.2 | E14: =MAX(Dataset!$I$2:$I$201) -> 769.46
A15: Sum | B15: =SUM(Dataset!$E$2:$E$201) -> 195217.76 | C15: =SUM(Dataset!$F$2:$F$201) -> 1999 | D15: =SUM(Dataset!$G$2:$G$201) -> 19.45 | E15: =SUM(Dataset!$I$2:$I$201) -> 68287.01
A16: Count | B16: =COUNT(Dataset!$E$2:$E$201) -> 200 | C16: =COUNT(Dataset!$F$2:$F$201) -> 200 | D16: =COUNT(Dataset!$G$2:$G$201) -> 200 | E16: =COUNT(Dataset!$I$2:$I$201) -> 200
A18: Advanced descriptive analytics
A19: Measure | B19: Sales | C19: Quantity | D19: Discount | E19: Profit
A20: 1st Quartile (Q1) | B20: =QUARTILE(Dataset!$E$2:$E$201,1) -> 761.8375 | C20: =QUARTILE(Dataset!$F$2:$F$201,1) -> 5 | D20: =QUARTILE(Dataset!$G$2:$G$201,1) -> 0.05 | E20: =QUARTILE(Dataset!$I$2:$I$201,1) -> 240.8425
A21: 3rd Quartile (Q3) | B21: =QUARTILE(Dataset!$E$2:$E$201,3) -> 1173.0075 | C21: =QUARTILE(Dataset!$F$2:$F$201,3) -> 15 | D21: =QUARTILE(Dataset!$G$2:$G$201,3) -> 0.15 | E21: =QUARTILE(Dataset!$I$2:$I$201,3) -> 440.0375
A22: Interquartile Range (IQR) | B22: =B21-B20 -> 411.17 | C22: =C21-C20 -> 10 | D22: =D21-D20 -> 0.1 | E22: =E21-E20 -> 199.195
A23: 90th Percentile | B23: =PERCENTILE(Dataset!$E$2:$E$201,0.9) -> 1361.458 | C23: =PERCENTILE(Dataset!$F$2:$F$201,0.9) -> 18 | D23: =PERCENTILE(Dataset!$G$2:$G$201,0.9) -> 0.2 | E23: =PERCENTILE(Dataset!$I$2:$I$201,0.9) -> 511.364
A24: Coefficient of Variation | B24: =STDEV(Dataset!$E$2:$E$201)/AVERAGE(Dataset!$E$2:$E$201) -> 0.30660505 | C24: =STDEV(Dataset!$F$2:$F$201)/AVERAGE(Dataset!$F$2:$F$201) -> 0.56494518 | D24: =STDEV(Dataset!$G$2:$G$201)/AVERAGE(Dataset!$G$2:$G$201) -> 0.74371512 | E24: =STDEV(Dataset!$I$2:$I$201)/AVERAGE(Dataset!$I$2:$I$201) -> 0.39763403
A25: Lower Outlier Fence | B25: =B20-1.5*B22 -> 145.0825 | C25: =C20-1.5*C22 -> -10 | D25: =D20-1.5*D22 -> -0.1 | E25: =E20-1.5*E22 -> -57.95
A26: Upper Outlier Fence | B26: =B21+1.5*B22 -> 1789.7625 | C26: =C21+1.5*C22 -> 30 | D26: =D21+1.5*D22 -> 0.3 | E26: =E21+1.5*E22 -> 738.83
A27: Outliers (count) | B27: =COUNTIF(Dataset!$E$2:$E$201,"<"&B25)+COUNTIF(Dataset!$E$2:$E$201,">"&B26) -> 1 | C27: =COUNTIF(Dataset!$F$2:$F$201,"<"&C25)+COUNTIF(Dataset!$F$2:$F$201,">"&C26) -> 0 | D27: =COUNTIF(Dataset!$G$2:$G$201,"<"&D25)+COUNTIF(Dataset!$G$2:$G$201,">"&D26) -> 0 | E27: =COUNTIF(Dataset!$I$2:$I$201,"<"&E25)+COUNTIF(Dataset!$I$2:$I$201,">"&E26) -> 2
A28: 95% Confidence Interval (±) | B28: =CONFIDENCE(0.05,STDEV(Dataset!$E$2:$E$201),COUNT(Dataset!$E$2:$E$201)) -> 41.476465 | C28: =CONFIDENCE(0.05,STDEV(Dataset!$F$2:$F$201),COUNT(Dataset!$F$2:$F$201)) -> 0.7825682 | D28: =CONFIDENCE(0.05,STDEV(Dataset!$G$2:$G$201),COUNT(Dataset!$G$2:$G$201)) -> 0.010023729 | E28: =CONFIDENCE(0.05,STDEV(Dataset!$I$2:$I$201),COUNT(Dataset!$I$2:$I$201)) -> 18.815889
A31: Correlation matrix
B32: Sales | C32: Quantity | D32: Discount | E32: Profit
A33: Sales | B33: =CORREL(Dataset!$E$2:$E$201,Dataset!$E$2:$E$201) -> 1 | C33: =CORREL(Dataset!$E$2:$E$201,Dataset!$F$2:$F$201) -> -0.018540147 | D33: =CORREL(Dataset!$E$2:$E$201,Dataset!$G$2:$G$201) -> 0.066821872 | E33: =CORREL(Dataset!$E$2:$E$201,Dataset!$I$2:$I$201) -> 0.77340306
A34: Quantity | B34: =CORREL(Dataset!$F$2:$F$201,Dataset!$E$2:$E$201) -> -0.018540147 | C34: =CORREL(Dataset!$F$2:$F$201,Dataset!$F$2:$F$201) -> 1 | D34: =CORREL(Dataset!$F$2:$F$201,Dataset!$G$2:$G$201) -> 0.0073488225 | E34: =CORREL(Dataset!$F$2:$F$201,Dataset!$I$2:$I$201) -> -0.015757885
A35: Discount | B35: =CORREL(Dataset!$G$2:$G$201,Dataset!$E$2:$E$201) -> 0.066821872 | C35: =CORREL(Dataset!$G$2:$G$201,Dataset!$F$2:$F$201) -> 0.0073488225 | D35: =CORREL(Dataset!$G$2:$G$201,Dataset!$G$2:$G$201) -> 1 | E35: =CORREL(Dataset!$G$2:$G$201,Dataset!$I$2:$I$201) -> -0.16557933
A36: Profit | B36: =CORREL(Dataset!$I$2:$I$201,Dataset!$E$2:$E$201) -> 0.77340306 | C36: =CORREL(Dataset!$I$2:$I$201,Dataset!$F$2:$F$201) -> -0.015757885 | D36: =CORREL(Dataset!$I$2:$I$201,Dataset!$G$2:$G$201) -> -0.16557933 | E36: =CORREL(Dataset!$I$2:$I$201,Dataset!$I$2:$I$201) -> 1
A39: Histogram data – Sales distribution
A40: First bin start (input) | B40: 250
A41: Bin width (input) | B41: 200
A43: Bin (Sales) | B43: From (>) | C43: To (≤) | D43: Frequency
A44: =B44&" - "&C44 -> 250 - 450 | B44: =$B$40 -> 250 | C44: =B44+$B$41 -> 450 | D44: =COUNTIFS(Dataset!$E$2:$E$201,">"&B44,Dataset!$E$2:$E$201,"<="&C44) -> 7
A45: =B45&" - "&C45 -> 450 - 650 | B45: =C44 -> 450 | C45: =B45+$B$41 -> 650 | D45: =COUNTIFS(Dataset!$E$2:$E$201,">"&B45,Dataset!$E$2:$E$201,"<="&C45) -> 19
A46: =B46&" - "&C46 -> 650 - 850 | B46: =C45 -> 650 | C46: =B46+$B$41 -> 850 | D46: =COUNTIFS(Dataset!$E$2:$E$201,">"&B46,Dataset!$E$2:$E$201,"<="&C46) -> 44
A47: =B47&" - "&C47 -> 850 - 1050 | B47: =C46 -> 850 | C47: =B47+$B$41 -> 1050 | D47: =COUNTIFS(Dataset!$E$2:$E$201,">"&B47,Dataset!$E$2:$E$201,"<="&C47) -> 51
...

Sheet Monthly Trend
A1: Monthly Sales Trend with up / down arrows (custom number format + icon set)
A2: Apr-24 starts on 10-Apr-2024 and Apr-25 ends on 07-Apr-2025, so both are partial months.
A3: Month | B3: Sales | C3: Profit | D3: Orders | E3: Growth % (MoM) | F3: Arrow | G3: Profit Margin
A4: =DATE(2024,4,1) -> 45383 | B4: =SUMIFS(Dataset!$E$2:$E$201,Dataset!$K$2:$K$201,A4) -> 19029.96 | C4: =SUMIFS(Dataset!$I$2:$I$201,Dataset!$K$2:$K$201,A4) -> 6244.01 | D4: =COUNTIFS(Dataset!$K$2:$K$201,A4) -> 19 | E4: ="" | F4: =IF(E4="","",IF(E4>0,"▲",IF(E4<0,"▼","▬"))) | G4: =C4/B4 -> 0.32811472
A5: =EDATE(A4,1) -> 45413 | B5: =SUMIFS(Dataset!$E$2:$E$201,Dataset!$K$2:$K$201,A5) -> 18507.34 | C5: =SUMIFS(Dataset!$I$2:$I$201,Dataset!$K$2:$K$201,A5) -> 6121.35 | D5: =COUNTIFS(Dataset!$K$2:$K$201,A5) -> 21 | E5: =IFERROR(B5/B4-1,"") -> -0.027463011 | F5: =IF(E5="","",IF(E5>0,"▲",IF(E5<0,"▼","▬"))) -> ▼ | G5: =C5/B5 -> 0.33075256
A6: =EDATE(A5,1) -> 45444 | B6: =SUMIFS(Dataset!$E$2:$E$201,Dataset!$K$2:$K$201,A6) -> 20187.51 | C6: =SUMIFS(Dataset!$I$2:$I$201,Dataset!$K$2:$K$201,A6) -> 6918 | D6: =COUNTIFS(Dataset!$K$2:$K$201,A6) -> 20 | E6: =IFERROR(B6/B5-1,"") -> 0.090783981 | F6: =IF(E6="","",IF(E6>0,"▲",IF(E6<0,"▼","▬"))) -> ▲ | G6: =C6/B6 -> 0.34268714
A7: =EDATE(A6,1) -> 45474 | B7: =SUMIFS(Dataset!$E$2:$E$201,Dataset!$K$2:$K$201,A7) -> 11609.04 | C7: =SUMIFS(Dataset!$I$2:$I$201,Dataset!$K$2:$K$201,A7) -> 3743.85 | D7: =COUNTIFS(Dataset!$K$2:$K$201,A7) -> 12 | E7: =IFERROR(B7/B6-1,"") -> -0.42493948 | F7: =IF(E7="","",IF(E7>0,"▲",IF(E7<0,"▼","▬"))) -> ▼ | G7: =C7/B7 -> 0.32249437
A8: =EDATE(A7,1) -> 45505 | B8: =SUMIFS(Dataset!$E$2:$E$201,Dataset!$K$2:$K$201,A8) -> 10091.7 | C8: =SUMIFS(Dataset!$I$2:$I$201,Dataset!$K$2:$K$201,A8) -> 3302.84 | D8: =COUNTIFS(Dataset!$K$2:$K$201,A8) -> 10 | E8: =IFERROR(B8/B7-1,"") -> -0.13070331 | F8: =IF(E8="","",IF(E8>0,"▲",IF(E8<0,"▼","▬"))) -> ▼ | G8: =C8/B8 -> 0.32728282
A9: =EDATE(A8,1) -> 45536 | B9: =SUMIFS(Dataset!$E$2:$E$201,Dataset!$K$2:$K$201,A9) -> 20533.5 | C9: =SUMIFS(Dataset!$I$2:$I$201,Dataset!$K$2:$K$201,A9) -> 7457.52 | D9: =COUNTIFS(Dataset!$K$2:$K$201,A9) -> 20 | E9: =IFERROR(B9/B8-1,"") -> 1.0346919 | F9: =IF(E9="","",IF(E9>0,"▲",IF(E9<0,"▼","▬"))) -> ▲ | G9: =C9/B9 -> 0.36318796
A10: =EDATE(A9,1) -> 45566 | B10: =SUMIFS(Dataset!$E$2:$E$201,Dataset!$K$2:$K$201,A10) -> 14215.24 | C10: =SUMIFS(Dataset!$I$2:$I$201,Dataset!$K$2:$K$201,A10) -> 4861.7 | D10: =COUNTIFS(Dataset!$K$2:$K$201,A10) -> 14 | E10: =IFERROR(B10/B9-1,"") -> -0.30770497 | F10: =IF(E10="","",IF(E10>0,"▲",IF(E10<0,"▼","▬"))) -> ▼ | G10: =C10/B10 -> 0.34200618
A11: =EDATE(A10,1) -> 45597 | B11: =SUMIFS(Dataset!$E$2:$E$201,Dataset!$K$2:$K$201,A11) -> 20135.03 | C11: =SUMIFS(Dataset!$I$2:$I$201,Dataset!$K$2:$K$201,A11) -> 6814.88 | D11: =COUNTIFS(Dataset!$K$2:$K$201,A11) -> 20 | E11: =IFERROR(B11/B10-1,"") -> 0.41643968 | F11: =IF(E11="","",IF(E11>0,"▲",IF(E11<0,"▼","▬"))) -> ▲ | G11: =C11/B11 -> 0.33845889
A12: =EDATE(A11,1) -> 45627 | B12: =SUMIFS(Dataset!$E$2:$E$201,Dataset!$K$2:$K$201,A12) -> 11120.04 | C12: =SUMIFS(Dataset!$I$2:$I$201,Dataset!$K$2:$K$201,A12) -> 3549.99 | D12: =COUNTIFS(Dataset!$K$2:$K$201,A12) -> 11 | E12: =IFERROR(B12/B11-1,"") -> -0.44772667 | F12: =IF(E12="","",IF(E12>0,"▲",IF(E12<0,"▼","▬"))) -> ▼ | G12: =C12/B12 -> 0.31924256
A13: =EDATE(A12,1) -> 45658 | B13: =SUMIFS(Dataset!$E$2:$E$201,Dataset!$K$2:$K$201,A13) -> 14914.65 | C13: =SUMIFS(Dataset!$I$2:$I$201,Dataset!$K$2:$K$201,A13) -> 5763.4 | D13: =COUNTIFS(Dataset!$K$2:$K$201,A13) -> 16 | E13: =IFERROR(B13/B12-1,"") -> 0.34124068 | F13: =IF(E13="","",IF(E13>0,"▲",IF(E13<0,"▼","▬"))) -> ▲ | G13: =C13/B13 -> 0.38642543
A14: =EDATE(A13,1) -> 45689 | B14: =SUMIFS(Dataset!$E$2:$E$201,Dataset!$K$2:$K$201,A14) -> 14006.36 | C14: =SUMIFS(Dataset!$I$2:$I$201,Dataset!$K$2:$K$201,A14) -> 5039.23 | D14: =COUNTIFS(Dataset!$K$2:$K$201,A14) -> 14 | E14: =IFERROR(B14/B13-1,"") -> -0.060899183 | F14: =IF(E14="","",IF(E14>0,"▲",IF(E14<0,"▼","▬"))) -> ▼ | G14: =C14/B14 -> 0.35978156
A15: =EDATE(A14,1) -> 45717 | B15: =SUMIFS(Dataset!$E$2:$E$201,Dataset!$K$2:$K$201,A15) -> 17655.22 | C15: =SUMIFS(Dataset!$I$2:$I$201,Dataset!$K$2:$K$201,A15) -> 7071.39 | D15: =COUNTIFS(Dataset!$K$2:$K$201,A15) -> 19 | E15: =IFERROR(B15/B14-1,"") -> 0.26051451 | F15: =IF(E15="","",IF(E15>0,"▲",IF(E15<0,"▼","▬"))) -> ▲ | G15: =C15/B15 -> 0.40052687
A16: =EDATE(A15,1) -> 45748 | B16: =SUMIFS(Dataset!$E$2:$E$201,Dataset!$K$2:$K$201,A16) -> 3212.17 | C16: =SUMIFS(Dataset!$I$2:$I$201,Dataset!$K$2:$K$201,A16) -> 1398.85 | D16: =COUNTIFS(Dataset!$K$2:$K$201,A16) -> 4 | E16: =IFERROR(B16/B15-1,"") -> -0.81806117 | F16: =IF(E16="","",IF(E16>0,"▲",IF(E16<0,"▼","▬"))) -> ▼ | G16: =C16/B16 -> 0.43548442
A17: Total | B17: =SUM(B4:B16) -> 195217.76 | C17: =SUM(C4:C16) -> 68287.01 | D17: =SUM(D4:D16) -> 200

Sheet Pivot Summary
A1: Pivot Summary – PivotTable-style summaries built with SUMIFS
A3: Total Sales by Region × Product Category
A4: Region | B4: Books | C4: Clothing | D4: Electronics | E4: Furniture | F4: Office Supplies | G4: Grand Total
A5: Central | B5: =SUMIFS(Dataset!$E$2:$E$201,Dataset!$C$2:$C$201,$A5,Dataset!$D$2:$D$201,B$4) -> 11297.15 | C5: =SUMIFS(Dataset!$E$2:$E$201,Dataset!$C$2:$C$201,$A5,Dataset!$D$2:$D$201,C$4) -> 12200.26 | D5: =SUMIFS(Dataset!$E$2:$E$201,Dataset!$C$2:$C$201,$A5,Dataset!$D$2:$D$201,D$4) -> 6621.24 | E5: =SUMIFS(Dataset!$E$2:$E$201,Dataset!$C$2:$C$201,$A5,Dataset!$D$2:$D$201,E$4) -> 4876.96 | F5: =SUMIFS(Dataset!$E$2:$E$201,Dataset!$C$2:$C$201,$A5,Dataset!$D$2:$D$201,F$4) -> 8472.72 | G5: =SUM(B5:F5) -> 43468.33
A6: East | B6: =SUMIFS(Dataset!$E$2:$E$201,Dataset!$C$2:$C$201,$A6,Dataset!$D$2:$D$201,B$4) -> 11389.09 | C6: =SUMIFS(Dataset!$E$2:$E$201,Dataset!$C$2:$C$201,$A6,Dataset!$D$2:$D$201,C$4) -> 2401.45 | D6: =SUMIFS(Dataset!$E$2:$E$201,Dataset!$C$2:$C$201,$A6,Dataset!$D$2:$D$201,D$4) -> 2869.54 | E6: =SUMIFS(Dataset!$E$2:$E$201,Dataset!$C$2:$C$201,$A6,Dataset!$D$2:$D$201,E$4) -> 7592.34 | F6: =SUMIFS(Dataset!$E$2:$E$201,Dataset!$C$2:$C$201,$A6,Dataset!$D$2:$D$201,F$4) -> 8189.22 | G6: =SUM(B6:F6) -> 32441.64
A7: North | B7: =SUMIFS(Dataset!$E$2:$E$201,Dataset!$C$2:$C$201,$A7,Dataset!$D$2:$D$201,B$4) -> 8037.01 | C7: =SUMIFS(Dataset!$E$2:$E$201,Dataset!$C$2:$C$201,$A7,Dataset!$D$2:$D$201,C$4) -> 8422.82 | D7: =SUMIFS(Dataset!$E$2:$E$201,Dataset!$C$2:$C$201,$A7,Dataset!$D$2:$D$201,D$4) -> 8191.71 | E7: =SUMIFS(Dataset!$E$2:$E$201,Dataset!$C$2:$C$201,$A7,Dataset!$D$2:$D$201,E$4) -> 6978.08 | F7: =SUMIFS(Dataset!$E$2:$E$201,Dataset!$C$2:$C$201,$A7,Dataset!$D$2:$D$201,F$4) -> 3345.8 | G7: =SUM(B7:F7) -> 34975.42
A8: South | B8: =SUMIFS(Dataset!$E$2:$E$201,Dataset!$C$2:$C$201,$A8,Dataset!$D$2:$D$201,B$4) -> 9588.04 | C8: =SUMIFS(Dataset!$E$2:$E$201,Dataset!$C$2:$C$201,$A8,Dataset!$D$2:$D$201,C$4) -> 8393.63 | D8: =SUMIFS(Dataset!$E$2:$E$201,Dataset!$C$2:$C$201,$A8,Dataset!$D$2:$D$201,D$4) -> 11989.07 | E8: =SUMIFS(Dataset!$E$2:$E$201,Dataset!$C$2:$C$201,$A8,Dataset!$D$2:$D$201,E$4) -> 7982.73 | F8: =SUMIFS(Dataset!$E$2:$E$201,Dataset!$C$2:$C$201,$A8,Dataset!$D$2:$D$201,F$4) -> 2295.32 | G8: =SUM(B8:F8) -> 40248.79
A9: West | B9: =SUMIFS(Dataset!$E$2:$E$201,Dataset!$C$2:$C$201,$A9,Dataset!$D$2:$D$201,B$4) -> 6691.17 | C9: =SUMIFS(Dataset!$E$2:$E$201,Dataset!$C$2:$C$201,$A9,Dataset!$D$2:$D$201,C$4) -> 10509.43 | D9: =SUMIFS(Dataset!$E$2:$E$201,Dataset!$C$2:$C$201,$A9,Dataset!$D$2:$D$201,D$4) -> 11372.44 | E9: =SUMIFS(Dataset!$E$2:$E$201,Dataset!$C$2:$C$201,$A9,Dataset!$D$2:$D$201,E$4) -> 9182.78 | F9: =SUMIFS(Dataset!$E$2:$E$201,Dataset!$C$2:$C$201,$A9,Dataset!$D$2:$D$201,F$4) -> 6327.76 | G9: =SUM(B9:F9) -> 44083.58
A10: Grand Total | B10: =SUM(B5:B9) -> 47002.46 | C10: =SUM(C5:C9) -> 41927.59 | D10: =SUM(D5:D9) -> 41044 | E10: =SUM(E5:E9) -> 36612.89 | F10: =SUM(F5:F9) -> 28630.82 | G10: =SUM(G5:G9) -> 195217.76
A12: Total Profit by Region × Product Category
A13: Region | B13: Books | C13: Clothing | D13: Electronics | E13: Furniture | F13: Office Supplies | G13: Grand Total
A14: Central | B14: =SUMIFS(Dataset!$I$2:$I$201,Dataset!$C$2:$C$201,$A14,Dataset!$D$2:$D$201,B$13) -> 4201.27 | C14: =SUMIFS(Dataset!$I$2:$I$201,Dataset!$C$2:$C$201,$A14,Dataset!$D$2:$D$201,C$13) -> 5395.6 | D14: =SUMIFS(Dataset!$I$2:$I$201,Dataset!$C$2:$C$201,$A14,Dataset!$D$2:$D$201,D$13) -> 1515.04 | E14: =SUMIFS(Dataset!$I$2:$I$201,Dataset!$C$2:$C$201,$A14,Dataset!$D$2:$D$201,E$13) -> 1566.46 | F14: =SUMIFS(Dataset!$I$2:$I$201,Dataset!$C$2:$C$201,$A14,Dataset!$D$2:$D$201,F$13) -> 3390.03 | G14: =SUM(B14:F14) -> 16068.4
A15: East | B15: =SUMIFS(Dataset!$I$2:$I$201,Dataset!$C$2:$C$201,$A15,Dataset!$D$2:$D$201,B$13) -> 4212.63 | C15: =SUMIFS(Dataset!$I$2:$I$201,Dataset!$C$2:$C$201,$A15,Dataset!$D$2:$D$201,C$13) -> 1025.15 | D15: =SUMIFS(Dataset!$I$2:$I$201,Dataset!$C$2:$C$201,$A15,Dataset!$D$2:$D$201,D$13) -> 662.68 | E15: =SUMIFS(Dataset!$I$2:$I$201,Dataset!$C$2:$C$201,$A15,Dataset!$D$2:$D$201,E$13) -> 2428.08 | F15: =SUMIFS(Dataset!$I$2:$I$201,Dataset!$C$2:$C$201,$A15,Dataset!$D$2:$D$201,F$13) -> 3310.05 | G15: =SUM(B15:F15) -> 11638.59
A16: North | B16: =SUMIFS(Dataset!$I$2:$I$201,Dataset!$C$2:$C$201,$A16,Dataset!$D$2:$D$201,B$13) -> 2778.44 | C16: =SUMIFS(Dataset!$I$2:$I$201,Dataset!$C$2:$C$201,$A16,Dataset!$D$2:$D$201,C$13) -> 3691.09 | D16: =SUMIFS(Dataset!$I$2:$I$201,Dataset!$C$2:$C$201,$A16,Dataset!$D$2:$D$201,D$13) -> 1783.05 | E16: =SUMIFS(Dataset!$I$2:$I$201,Dataset!$C$2:$C$201,$A16,Dataset!$D$2:$D$201,E$13) -> 2217.72 | F16: =SUMIFS(Dataset!$I$2:$I$201,Dataset!$C$2:$C$201,$A16,Dataset!$D$2:$D$201,F$13) -> 1431.98 | G16: =SUM(B16:F16) -> 11902.28
A17: South | B17: =SUMIFS(Dataset!$I$2:$I$201,Dataset!$C$2:$C$201,$A17,Dataset!$D$2:$D$201,B$13) -> 3416.81 | C17: =SUMIFS(Dataset!$I$2:$I$201,Dataset!$C$2:$C$201,$A17,Dataset!$D$2:$D$201,C$13) -> 3944.21 | D17: =SUMIFS(Dataset!$I$2:$I$201,Dataset!$C$2:$C$201,$A17,Dataset!$D$2:$D$201,D$13) -> 2783.44 | E17: =SUMIFS(Dataset!$I$2:$I$201,Dataset!$C$2:$C$201,$A17,Dataset!$D$2:$D$201,E$13) -> 2540.36 | F17: =SUMIFS(Dataset!$I$2:$I$201,Dataset!$C$2:$C$201,$A17,Dataset!$D$2:$D$201,F$13) -> 1007.09 | G17: =SUM(B17:F17) -> 13691.91
A18: West | B18: =SUMIFS(Dataset!$I$2:$I$201,Dataset!$C$2:$C$201,$A18,Dataset!$D$2:$D$201,B$13) -> 2292.48 | C18: =SUMIFS(Dataset!$I$2:$I$201,Dataset!$C$2:$C$201,$A18,Dataset!$D$2:$D$201,C$13) -> 4728.44 | D18: =SUMIFS(Dataset!$I$2:$I$201,Dataset!$C$2:$C$201,$A18,Dataset!$D$2:$D$201,D$13) -> 2437.94 | E18: =SUMIFS(Dataset!$I$2:$I$201,Dataset!$C$2:$C$201,$A18,Dataset!$D$2:$D$201,E$13) -> 2826.52 | F18: =SUMIFS(Dataset!$I$2:$I$201,Dataset!$C$2:$C$201,$A18,Dataset!$D$2:$D$201,F$13) -> 2700.45 | G18: =SUM(B18:F18) -> 14985.83
A19: Grand Total | B19: =SUM(B14:B18) -> 16901.63 | C19: =SUM(C14:C18) -> 18784.49 | D19: =SUM(D14:D18) -> 9182.15 | E19: =SUM(E14:E18) -> 11579.14 | F19: =SUM(F14:F18) -> 11839.6 | G19: =SUM(G14:G18) -> 68287.01
A21: Sales by Region
A22: Region | B22: Sales | C22: Orders | D22: Share %
A23: Central | B23: =SUMIFS(Dataset!$E$2:$E$201,Dataset!$C$2:$C$201,A23) -> 43468.33 | C23: =COUNTIF(Dataset!$C$2:$C$201,A23) -> 44 | D23: =B23/$B$28 -> 0.22266586
A24: East | B24: =SUMIFS(Dataset!$E$2:$E$201,Dataset!$C$2:$C$201,A24) -> 32441.64 | C24: =COUNTIF(Dataset!$C$2:$C$201,A24) -> 32 | D24: =B24/$B$28 -> 0.16618181
A25: North | B25: =SUMIFS(Dataset!$E$2:$E$201,Dataset!$C$2:$C$201,A25) -> 34975.42 | C25: =COUNTIF(Dataset!$C$2:$C$201,A25) -> 39 | D25: =B25/$B$28 -> 0.17916106
A26: South | B26: =SUMIFS(Dataset!$E$2:$E$201,Dataset!$C$2:$C$201,A26) -> 40248.79 | C26: =COUNTIF(Dataset!$C$2:$C$201,A26) -> 42 | D26: =B26/$B$28 -> 0.20617381
A27: West | B27: =SUMIFS(Dataset!$E$2:$E$201,Dataset!$C$2:$C$201,A27) -> 44083.58 | C27: =COUNTIF(Dataset!$C$2:$C$201,A27) -> 43 | D27: =B27/$B$28 -> 0.22581747
A28: Total | B28: =SUM(B23:B27) -> 195217.76 | C28: =SUM(C23:C27) -> 200
A30: Sales by Product Category
A31: Category | B31: Sales | C31: Orders | D31: Share %
A32: Books | B32: =SUMIFS(Dataset!$E$2:$E$201,Dataset!$D$2:$D$201,A32) -> 47002.46 | C32: =COUNTIF(Dataset!$D$2:$D$201,A32) -> 49 | D32: =B32/$B$37 -> 0.24076938
A33: Clothing | B33: =SUMIFS(Dataset!$E$2:$E$201,Dataset!$D$2:$D$201,A33) -> 41927.59 | C33: =COUNTIF(Dataset!$D$2:$D$201,A33) -> 41 | D33: =B33/$B$37 -> 0.21477344
A34: Electronics | B34: =SUMIFS(Dataset!$E$2:$E$201,Dataset!$D$2:$D$201,A34) -> 41044 | C34: =COUNTIF(Dataset!$D$2:$D$201,A34) -> 43 | D34: =B34/$B$37 -> 0.21024726
A35: Furniture | B35: =SUMIFS(Dataset!$E$2:$E$201,Dataset!$D$2:$D$201,A35) -> 36612.89 | C35: =COUNTIF(Dataset!$D$2:$D$201,A35) -> 36 | D35: =B35/$B$37 -> 0.18754897
A36: Office Supplies | B36: =SUMIFS(Dataset!$E$2:$E$201,Dataset!$D$2:$D$201,A36) -> 28630.82 | C36: =COUNTIF(Dataset!$D$2:$D$201,A36) -> 31 | D36: =B36/$B$37 -> 0.14666094
A37: Total | B37: =SUM(B32:B36) -> 195217.76 | C37: =SUM(C32:C36) -> 200
A39: Create the real PivotTable with a dashboard (do by hand in Excel)
A40: 1. Click any cell in Dataset > Insert > PivotTable > New Worksheet (name it 'Pivot').
A41: 2. Rows = Region, Columns = Product_Category, Values = Sum of Sales.
A42: 3. Insert > PivotChart: Clustered Bar (region), Line (Order_Date grouped by Months), Pie (Product_Category).
A43: 4. PivotTable Analyze > Insert Slicer (Region, Product_Category) and Insert Timeline (Order_Date); connect them to all pivots.
A44: 5. Arrange the pivot charts and slicers on a new sheet to form the pivot dashboard.

Sheet Charts
A1: Charts – bar, line, pie, histogram, what-if and regression

Sheet Dashboard
A1: PR. 2 ANALYZER – SALES DASHBOARD
A2: ="Orders from "&TEXT(MIN(Dataset!$H$2:$H$201),"dd-mmm-yyyy")&" to "&TEXT(MAX(Dataset!$H$2:$H$201),"dd-mmm-yyyy")&" | Last refreshed (NOW): "&TEXT(NOW(),"dd-mmm-yyyy hh:mm") -> Orders from 10-Apr-2024 to 07-Apr-2025 | Last refreshed (NOW): 09-Oct-2026 11:17
A3: TOTAL SALES | C3: TOTAL PROFIT | E3: PROFIT MARGIN | G3: TOTAL ORDERS
A4: =SUM(Dataset!$E$2:$E$201) -> 195217.76 | C4: =SUM(Dataset!$I$2:$I$201) -> 68287.01 | E4: =C4/A4 -> 0.34979917 | G4: =COUNTA(Dataset!$A$2:$A$201) -> 200
A6: TOP CUSTOMER | C6: BEST REGION | E6: BEST CATEGORY | G6: LAST FULL MONTH GROWTH
A7: =INDEX('Customer Analysis'!A4:A33,MATCH(MAX('Customer Analysis'!C4:C33),'Customer Analysis'!C4:C33,0)) -> CUST015 | C7: =INDEX('Pivot Summary'!A23:A27,MATCH(MAX('Pivot Summary'!B23:B27),'Pivot Summary'!B23:B27,0)) -> West | E7: =INDEX('Pivot Summary'!A32:A36,MATCH(MAX('Pivot Summary'!B32:B36),'Pivot Summary'!B32:B36,0)) -> Books | G7: ='Monthly Trend'!E15 -> 0.26051451
A41: Key insights (update automatically)
A42: ="Total sales of "&TEXT(A4,"#,##0")&" from "&TEXT(G4,"#,##0")&" orders gave a profit of "&TEXT(C4,"#,##0")&" (margin "&TEXT(E4,"0.0%")&")." -> Total sales of 195,218 from 200 orders gave a profit of 68,287 (margin 35.0%).
A43: ="Top customer is "&A7&"; the top 10 customers contribute "&TEXT(SUM('Customer Analysis'!C4:C13)/A4,"0%")&" of total sales." -> Top customer is CUST015; the top 10 customers contribute 47% of total sales.
A44: ="Best region: "&C7&" and best category: "&E7&"." -> Best region: West and best category: Books.
A45: ="Discount effect: moving the discount from 10% to 20% changes total profit by "&TEXT('What-If Analysis'!C22-'What-If Analysis'!C20,"#,##0")&" (quantity assumed constant)." -> Discount effect: moving the discount from 10% to 20% changes total profit by -21,803 (quantity assumed constant).
A46: ="Regression: every extra 1 of Sales adds about "&TEXT(Regression!B18,"0.00")&" of Profit (R² = "&TEXT(Regression!B6,"0.00")&")." -> Regression: every extra 1 of Sales adds about 0.35 of Profit (R² = 0.60).
A47: ="Last full month ("&TEXT('Monthly Trend'!A15,"mmm-yy")&") sales were "&TEXT('Monthly Trend'!B15,"#,##0")&", "&IF(G7>=0,"up ","down ")&TEXT(ABS(G7),"0.0%")&" versus the prior month." -> Last full month (Mar-25) sales were 17,655, up 26.1% versus the prior month.
